<?xml version="1.0" ?>
<sdf version="1.8">
  <world name="sensor_world">
    <physics name="1ms" type="ignored">
      <max_step_size>0.001</max_step_size>
      <real_time_factor>1.0</real_time_factor>
    </physics>
    <plugin filename="ignition-gazebo-physics-system" name="ignition::gazebo::systems::Physics">
    </plugin>
    <plugin filename="ignition-gazebo-user-commands-system" name="ignition::gazebo::systems::UserCommands">
    </plugin>
    <plugin filename="ignition-gazebo-scene-broadcaster-system" name="ignition::gazebo::systems::SceneBroadcaster">
    </plugin>
    <plugin filename="ignition-gazebo-imu-system" name="ignition::gazebo::systems::Imu">
    </plugin>
    <plugin filename="ignition-gazebo-sensors-system" name="ignition::gazebo::systems::Sensors">
      <render_engine>ogre2</render_engine>
    </plugin>
    <plugin filename="ignition-gazebo-contact-system" name="ignition::gazebo::systems::Contact">
    </plugin>

    <light type="directional" name="sun">
      <cast_shadows>true</cast_shadows>
      <pose>0 0 10 0 0 0</pose>
      <diffuse>0.8 0.8 0.8 1</diffuse>
      <specular>0.2 0.2 0.2 1</specular>
      <attenuation>
        <range>1000</range>
        <constant>0.9</constant>
        <linear>0.01</linear>
        <quadratic>0.001</quadratic>
      </attenuation>
      <direction>-0.5 0.1 -0.9</direction>
    </light>

    <model name="ground_plane">
      <static>true</static>
      <link name="link">
        <collision name="collision">
          <geometry>
            <plane>
              <normal>0 0 1</normal>
            </plane>
          </geometry>
        </collision>
        <visual name="visual">
          <geometry>
            <plane>
              <normal>0 0 1</normal>
              <size>100 100</size>
            </plane>
          </geometry>
          <material>
            <ambient>0.8 0.8 0.8 1</ambient>
            <diffuse>0.8 0.8 0.8 1</diffuse>
            <specular>0.8 0.8 0.8 1</specular>
          </material>
        </visual>
      </link>
    </model>

    <model name='vehicle_blue' canonical_link='chassis'>
      <pose relative_to='world'>0 0 1 0 0 0</pose>

      <frame name="lidar_frame" attached_to='chassis'>
        <pose>0.8 0 0.5 0 0 0</pose>
      </frame>

      <link name='chassis'>
        <pose relative_to='__model__'>0.5 0 0.4 0 0 0</pose>
        <inertial>
          <mass>1.14395</mass>
          <inertia>
            <ixx>0.126164</ixx>
            <ixy>0</ixy>
            <ixz>0</ixz>
            <iyy>0.416519</iyy>
            <iyz>0</iyz>
            <izz>0.481014</izz>
          </inertia>
        </inertial>
        <visual name='visual'>
          <geometry>
            <box>
              <size>2.0 1.0 0.5</size>
            </box>
          </geometry>
          <material>
            <ambient>0.0 0.0 1.0 1</ambient>
            <diffuse>0.0 0.0 1.0 1</diffuse>
            <specular>0.0 0.0 1.0 1</specular>
          </material>
        </visual>
        <collision name='collision'>
          <geometry>
            <box>
              <size>2.0 1.0 0.5</size>
            </box>
          </geometry>
        </collision>
        <sensor name="camera" type="camera">
          <pose>0 0 0.1 0 0 0</pose>
          <camera>
            <horizontal_fov>1.047</horizontal_fov>
            <image>
              <width>640</width>
              <height>480</height>
            </image>
            <clip>
              <near>0.1</near>
              <far>100</far>
            </clip>
          </camera>
          <always_on>true</always_on>
          <update_rate>30</update_rate>
          <visualize>true</visualize>
          <topic>/camera/image_raw</topic>
        </sensor>
      </link>
      <link name='left_wheel'>
        <pose relative_to="chassis">-0.5 0.6 0 -1.5707 0 0</pose>
        <inertial>
          <mass>2</mass>
          <inertia>
            <ixx>0.145833</ixx>
            <ixy>0</ixy>
            <ixz>0</ixz>
            <iyy>0.145833</iyy>
            <iyz>0</iyz>
            <izz>0.125</izz>
          </inertia>
        </inertial>
        <visual name='visual'>
          <geometry>
            <cylinder>
              <radius>0.4</radius>
              <length>0.2</length>
            </cylinder>
          </geometry>
          <material>
            <ambient>1.0 0.0 0.0 1</ambient>
            <diffuse>1.0 0.0 0.0 1</diffuse>
            <specular>1.0 0.0 0.0 1</specular>
          </material>
        </visual>
        <collision name='collision'>
          <geometry>
            <cylinder>
              <radius>0.4</radius>
              <length>0.2</length>
            </cylinder>
          </geometry>
        </collision>
      </link>

      <link name='right_wheel'>
        <pose relative_to="chassis">-0.5 -0.6 0 -1.5707 0 0</pose>
        <inertial>
          <mass>1</mass>
          <inertia>
            <ixx>0.145833</ixx>
            <ixy>0</ixy>
            <ixz>0</ixz>
            <iyy>0.145833</iyy>
            <iyz>0</iyz>
            <izz>0.125</izz>
          </inertia>
        </inertial>
        <visual name='visual'>
          <geometry>
            <cylinder>
              <radius>0.4</radius>
              <length>0.2</length>
            </cylinder>
          </geometry>
          <material>
            <ambient>1.0 0.0 0.0 1</ambient>
            <diffuse>1.0 0.0 0.0 1</diffuse>
            <specular>1.0 0.0 0.0 1</specular>
          </material>
        </visual>
        <collision name='collision'>
          <geometry>
            <cylinder>
              <radius>0.4</radius>
              <length>0.2</length>
            </cylinder>
          </geometry>
        </collision>
      </link>

      <frame name="caster_frame" attached_to='chassis'>
        <pose>0.8 0 -0.2 0 0 0</pose>
      </frame>

      <link name='caster'>
        <pose relative_to='caster_frame'/>
        <inertial>
          <mass>1</mass>
          <inertia>
            <ixx>0.1</ixx>
            <ixy>0</ixy>
            <ixz>0</ixz>
            <iyy>0.1</iyy>
            <iyz>0</iyz>
            <izz>0.1</izz>
          </inertia>
        </inertial>
        <visual name='visual'>
          <geometry>
            <sphere>
              <radius>0.2</radius>
            </sphere>
          </geometry>
          <material>
            <ambient>0.0 1 0.0 1</ambient>
            <diffuse>0.0 1 0.0 1</diffuse>
            <specular>0.0 1 0.0 1</specular>
          </material>
        </visual>
        <collision name='collision'>
          <geometry>
            <sphere>
              <radius>0.2</radius>
            </sphere>
          </geometry>
        </collision>
      </link>

      <joint name='left_wheel_joint' type='revolute'>
        <pose relative_to='left_wheel'/>
        <parent>chassis</parent>
        <child>left_wheel</child>
        <axis>
          <xyz expressed_in='__model__'>0 1 0</xyz>
          <limit>
            <lower>-1.79769e+308</lower>
            <upper>1.79769e+308</upper>
          </limit>
        </axis>
      </joint>

      <joint name='right_wheel_joint' type='revolute'>
        <pose relative_to='right_wheel'/>
        <parent>chassis</parent>
        <child>right_wheel</child>
        <axis>
          <xyz expressed_in='__model__'>0 1 0</xyz>
          <limit>
            <lower>-1.79769e+308</lower>
            <upper>1.79769e+308</upper>
          </limit>
        </axis>
      </joint>

      <joint name='caster_wheel' type='ball'>
        <parent>chassis</parent>
        <child>caster</child>
      </joint>

      <plugin filename="ignition-gazebo-diff-drive-system" name="ignition::gazebo::systems::DiffDrive">
        <left_joint>left_wheel_joint</left_joint>
        <right_joint>right_wheel_joint</right_joint>
        <wheel_separation>1.2</wheel_separation>
        <wheel_radius>0.4</wheel_radius>
        <odom_publish_frequency>1</odom_publish_frequency>
        <topic>cmd_vel</topic>
      </plugin>
    </model>

    <!-- Zigzag Line -->
    <model name="zigzag_line">
      <static>true</static>
      <link name="link">
        <visual name="visual">
          <geometry>
            <box>
              <size>1 1 0.01</size>
            </box>
          </geometry>
          <material>
            <ambient>0 0 0 1</ambient>
            <diffuse>0 0 0 1</diffuse>
            <specular>0 0 0 1</specular>
          </material>
        </visual>
      </link>
      <pose>0 0 0 0 0 0</pose>
    </model>

    <model name="zigzag_line_segment_1">
      <static>true</static>
      <link name="link">
        <visual name="visual">
          <geometry>
            <box>
              <size>1 1 0.01</size>
            </box>
          </geometry>
          <material>
            <ambient>0 0 0 1</ambient>
            <diffuse>0 0 0 1</diffuse>
            <specular>0 0 0 1</specular>
          </material>
        </visual>
      </link>
      <pose>1 1 0 0 0 0</pose>
    </model>

    <model name="zigzag_line_segment_2">
      <static>true</static>
      <link name="link">
        <visual name="visual">
          <geometry>
            <box>
              <size>1 1 0.01</size>
            </box>
          </geometry>
          <material>
            <ambient>0 0 0 1</ambient>
            <diffuse>0 0 0 1</diffuse>
            <specular>0 0 0 1</specular>
          </material>
        </visual>
      </link>
      <pose>2 0 0 0 0 0</pose>
    </model>

    <model name="zigzag_line_segment_3">
      <static>true</static>
      <link name="link">
        <visual name="visual">
          <geometry>
            <box>
              <size>1 1 0.01</size>
            </box>
          </geometry>
          <material>
            <ambient>0 0 0 1</ambient>
            <diffuse>0 0 0 1</diffuse>
            <specular>0 0 0 1</specular>
          </material>
        </visual>
      </link>
      <pose>3 -1 0 0 0 0</pose>
    </model>

    <model name="zigzag_line_segment_4">
      <static>true</static>
      <link name="link">
        <visual name="visual">
          <geometry>
            <box>
              <size>1 1 0.01</size>
            </box>
          </geometry>
          <material>
            <ambient>0 0 0 1</ambient>
            <diffuse>0 0 0 1</diffuse>
            <specular>0 0 0 1</specular>
          </material>
        </visual>
      </link>
      <pose>4 0 0 0 0 0</pose>
    </model>

    <model name="zigzag_line_segment_5">
      <static>true</static>
      <link name="link">
        <visual name="visual">
          <geometry>
            <box>
              <size>1 1 0.01</size>
            </box>
          </geometry>
          <material>
            <ambient>0 0 0 1</ambient>
            <diffuse>0 0 0 1</diffuse>
            <specular>0 0 0 1</specular>
          </material>
        </visual>
      </link>
      <pose>5 1 0 0 0 0</pose>
    </model>
  </world>
</sdf>